Workbook
Name \l: #REF!
Name \l: #REF!
Name \p: #REF!
Name \p: #REF!
Name _____dim4: #REF!
Name _____dim4: #REF!
Name _____rm4: #REF!
Name _____rm4: #REF!
Name ____dim4: #REF!
Name ____dim4: #REF!
Name ____rm4: #REF!
Name ____rm4: #REF!
Name ___bol1: #REF!
Name ___bol1: #REF!
Name ___dim4: #REF!
Name ___dim4: #REF!
Name ___rim4: #REF!
Name ___rim4: #REF!
Name ___rm4: #REF!
Name ___rm4: #REF!
Name __bol1: #REF!
Name __bol1: #REF!
Name __dim4: #REF!
Name __dim4: #REF!
Name __rim4: #REF!
Name __rim4: #REF!
Name __rm4: #REF!
Name __rm4: #REF!
Name _bol1: #REF!
Name _bol1: #REF!
Name _dim4: #REF!
Name _dim4: #REF!
Name _rim4: #REF!
Name _rim4: #REF!
Name _rm4: #REF!
Name _rm4: #REF!
Name A1_: #REF!
Name A1_: #REF!
Name A10_: #REF!
Name A10_: #REF!
Name A13_: #REF!
Name A13_: #REF!
Name A2_: #REF!
Name A2_: #REF!
Name A3_: #REF!
Name A3_: #REF!
Name A4_: #REF!
Name A4_: #REF!
Name A5_: #REF!
Name A5_: #REF!
Name A6_: #REF!
Name A6_: #REF!
Name A7_: #REF!
Name A7_: #REF!
Name A8_: #REF!
Name A8_: #REF!
Name A9_: #REF!
Name A9_: #REF!
Name acab: "$#REF!.$AQ$3"
Name accab: "$#REF!.$AS$3"

Sheet Detailed Info
A1: SUMMARY
A2: Sr. No. | B2: Description | C2: Remark
A3: 1 | B3: Name Of Project | C3: CONSTRUCTION OF PROPOSED SUB MARKET AT KHEDSHIVAPUR, DIST. PUNE FOR KRUSHI UTPANNA BAZAR SAMITI SHREE CHATRAPATI SHIVAJI MARKET YARD, PUNE
A4: 2 | B4: Name of Client | C4: Krushi Utpanna Bazar Samitee, Market Yard, Pune- 411037
A5: 3 | B5: Name of Contractor | C5: M/s UNIVASTU INDIA LTD
A6: 4 | B6: Cost Of Tender | C6: Rs. 24,73,80,891/- + GST
A7: 5 | B7: Completion Period | C7: 24 Months
A8: 6 | B8: Tender Submission Last Date | C8: 31/08/2019
A9: 7 | B9: Work Order No. | C9: जा. क्र. प्रजा/स्थापत्य/उ. बा. खेडशीवापूर/आठ. बाजार/वर्क ऑर्डर/ २०७७/२०१९-२० दि. १९/०९/२०१९
A10: 8 | B10: Work Order Date | C10: 19/09/2019
A11: 9 | B11: Our Final Quoted Amount | C11: Rs. 23,04,95,000/- (6.83 % Below) + GST | E11: 247280891
A12: 10 | E12: 230495000
E13: =E11-E12 -> 16785891
E14: =E13/E11 -> 0.067881877

Sheet Summary
A1: SUMMARY OF ESCALATION BILL
A2: Sr. No. | B2: Description | C2: Amount As per Escalation Rs. | D2: Amount As per Escalation Rs. Crore | E2: % wrt Total Amount
A3: 1 | B3: Labour | C3: =Labour!L18 -> 16473716 | D3: =C3/10000000 -> 1.6473716 | E3: =D3/$D$8 -> 0.28061932
A4: 2 | B4: Material Component | C4: ='Other material '!L18 -> 37875836 | D4: =C4/10000000 -> 3.7875836 | E4: =D4/$D$8 -> 0.64519089
A5: 3 | B5: P.O.L | C5: =P.O.L!L15 -> 1209443.5 | D5: =C5/10000000 -> 0.12094435 | E5: =D5/$D$8 -> 0.020602105
A6: 4 | B6: TMT Steel | C6: =TMT!L18 -> 2600901.7 | D6: =C6/10000000 -> 0.26009017 | E6: =D6/$D$8 -> 0.044304714
A7: 5 | B7: Cement | C7: =Cement!L13 -> 544955.16 | D7: =C7/10000000 -> 0.054495516 | E7: =D7/$D$8 -> 0.0092829662
A8: A | B8: Total Amount | C8: =SUM(C3:C7) -> 58704852 | D8: =C8/10000000 -> 5.8704852 | E8: =D8/$D$8 -> 1 | G8: =C8/Labour!B21 -> 0.25469035 | H8: =G8/6 -> 0.042448392
A9: B | B9: CGST 9% | C9: =C8*9% -> 5283436.7
A10: C | B10: SGST 9% | C10: =C8*9% -> 5283436.7
A11: D | B11: Total After GST | C11: =ROUNDUP(C8+C9+C10,0) -> 69271726

Sheet Labour
A1: STATEMENT SHOWING CALCULATION OF PRICE ESCALATION | G1: LABOUR
A2: Percentage of Components as per agrement | C2: BASIC INDICES | F2: STAR RATE OF CEMENT | H2: 4700 Rs per MT | J2: STAR RATE OF STEEL | L2: 45785 Rs per MT
A3: 1 LABOUR | B3: 0.22 | C3: 1. LABOUR | D3: =O14 -> 316.33333 | E3: Agreement No
A4: 2 MATERIAL | B4: 0.76 | C4: 2. MATERIAL | E4: Name of Agency | G4: : M/s UNIVASTU INDIA LTD
A5: 3 P.O.L. | B5: 0.02 | C5: 3. P.O.L. | E5: Name of Work | G5: Construction of sub market at khedshivapur
C6: 4. CEMENT | N6: =22/100 -> 0.22
C7: 5. STEEL | E7: Date of Receipt | G7: : 31.08.2019
J8: 40756 | K8: =202 -> 202 | L8: =AVERAGE(K8:K10) -> 204
J9: 40787 | K9: =204 -> 204
J10: 40817 | K10: =206 -> 206
K11: =SUM(K8:K10) -> 612
A12: Period of work done considered for price Escalation | B12: R. A. Bill No. | C12: Construction of work done (B) during the period (As per column No 1 After deducting the amount of Extra items | D12: Cost of Schedule A (Cement & Steel) Material consumed for the work done during the period | E12: P = ( 3- 4 ) | F12: Month | G12: Monthly Indices for Labour | H12: Quarterly average Index Labour | I12: VL = (P x 0.85) | J12: = P (-) Cost of Schedule "A" Material used | K12: K1/100 | L12: = VL x(K1/100)x(L1-L0)/L0 | M12: =5500/20 -> 275
A13: 1 | B13: 2 | C13: 3 | D13: 4 | E13: 5 | F13: 6 | G13: 7 | H13: 8 | I13: 9 | J13: 10 | K13: 11 | L13: 12
A14: 45961 | B14: R A Bill No 01 | C14: =B21 -> 230495000 | D14: ='Material details'!G10 -> 19375881 | E14: =C14-D14 -> 2.1111912e+08 | F14: 45870 | G14: 444.682 | H14: =G17/3 -> 448.33133 | I14: =E14*0.85 -> 1.7945125e+08 | K14: 0.22 | L14: =((I14*K14*(H14-$O$14))/$O$14) -> 16473716 | M14: 43586 | N14: 314 | O14: =AVERAGE(N14:N16) -> 316.33333
F15: 45901 | G15: 444.682 | M15: 43617 | N15: 316
F16: 45931 | G16: 455.63 | M16: 43647 | N16: 319
G17: =SUM(G14:G16) -> 1344.994 | N17: =SUM(N14:N16) -> 949
C18: =SUM(C14:C17) -> 230495000 | D18: =SUM(D14:D17) -> 19375881 | E18: =SUM(E14:E17) -> 2.1111912e+08 | I18: =SUM(I14:I17) -> 1.7945125e+08 | L18: =SUM(L14:L17) -> 16473716
B21: 230495000
B22: ='Material details'!G11 -> 19375881 | M22: 41913 | N22: =246*4.96 -> 1220.16 | O22: =AVERAGE(N22:N24) -> 1220.16
B23: =B21-B22 -> 2.1111912e+08 | M23: 41944 | N23: =246*4.96 -> 1220.16
M24: 41974 | N24: =246*4.96 -> 1220.16
B26: 1.6510133e+08

Sheet Other material 
A1: STATEMENT SHOWING CALCULATION OF PRICE ESCALATION | G1: OTHER MATERIAL
A2: Percentage of Components as per agrement | C2: BASIC INDICES | F2: STAR RATE OF CEMENT | H2: 4700 Rs per MT | J2: STAR RATE OF STEEL | L2: 45785 Rs per MT
A3: 1 LABOUR | B3: 0.22 | C3: 1. LABOUR | E3: Agreement No
A4: 2 MATERIAL | B4: 0.76 | C4: 2. MATERIAL | D4: =O14 -> 121.46667 | E4: Name of Agency | G4: : M/s UNIVASTU INDIA LTD
A5: 3 P.O.L. | B5: 0.02 | C5: 3. P.O.L. | E5: Name of Work | G5: Construction of sub market at khedshivapur
C6: 4. CEMENT
C7: 5. STEEL | E7: Date of Receipt | G7: : 31.08.2019
J8: 40817 | K8: 157 | L8: =K11/3 -> 0
J9: 40848 | K9: 157.4
J10: 40878 | K10: 157.3
A12: Period of work done considered for price Escalation | B12: R. A. Bill No. | C12: Construction of work done (B) during the period (As per column No 1 After deducting the amount of Extra items | D12: Cost of Schedule A (Cement & Steel) Material consumed for the work done during the period | E12: P = ( 3- 4 ) | F12: Month | G12: Monthly Indices for Other material | H12: Quarterly average Index Other material | I12: VL = (P x 0.85) | J12: = P (-) Cost of Schedule "A" Material used | K12: K2/100 | L12: =VL x (K2/100) x(M1-M0)/M0
A13: 1 | B13: 2 | C13: 3 | D13: 4 | E13: 5 | F13: 6 | G13: 7 | H13: 8 | I13: 9 | J13: 10 | K13: 11 | L13: 12
A14: 45961 | B14: R A Bill No 01 | C14: =Labour!C14 -> 230495000 | D14: ='Material details'!G10 -> 19375881 | E14: =C14-D14 -> 2.1111912e+08 | F14: 45870 | G14: 155.2 | H14: =AVERAGE(G14:G16) -> 155.2 | I14: =E14*0.85 -> 1.7945125e+08 | K14: 0.76 | L14: =((I14*K14*(H14-$O$14))/$O$14) -> 37875836 | M14: 43586 | N14: 121.6 | O14: =AVERAGE(N14:N16) -> 121.46667
F15: 45901 | G15: 155.2 | M15: 43617 | N15: 121.5
F16: 45931 | G16: 155.2 | M16: 43647 | N16: 121.3
G17: =SUM(G14:G16) -> 465.6 | N17: =SUM(N14:N16) -> 364.4
C18: =SUM(C14:C17) -> 230495000 | D18: =SUM(D14:D17) -> 19375881 | E18: =SUM(E14:E17) -> 2.1111912e+08 | I18: =SUM(I14:I17) -> 1.7945125e+08 | L18: =SUM(L14:L17) -> 37875836

Sheet P.O.L
A1: STATEMENT SHOWING CALCULATION OF PRICE ESCALATION | G1: P. O. L.
A2: Percentage of Components as per agrement | C2: BASIC INDICES | F2: STAR RATE OF CEMENT | H2: 4700 Rs per MT | J2: STAR RATE OF STEEL | L2: 45785 Rs per MT
A3: 1 LABOUR | B3: 0.22 | C3: 1. LABOUR | E3: Agreement No
A4: 2 MATERIAL | B4: 0.76 | C4: 2. MATERIAL | E4: Name of Agency | G4: : M/s UNIVASTU INDIA LTD
A5: 3 P.O.L. | B5: 0.02 | C5: 3. P.O.L. | D5: =O11 -> 67.57 | E5: Name of Work | G5: Construction of sub market at khedshivapur
C6: 4. CEMENT
C7: 5. STEEL | E7: Date of Receipt | G7: : 31.08.2019
A9: Period of work done considered for price Escalation | B9: R. A. Bill No. | C9: Construction of work done (B) during the period (As per column No 1 After deducting the amount of Extra items | D9: Cost of Schedule A (Cement & Steel) Material consumed for the work done during the period | E9: P = ( 3- 4 ) | F9: Month | G9: Monthly Indices for P.O.L | H9: Quarterly average Index P.O.L | I9: VL = (P x 0.85) | J9: = P (-) Cost of Schedule "A" Material used | K9: K3/100 | L9: =VL x(K1/100)x(P1-P0)/P0
A10: 1 | B10: 2 | C10: 3 | D10: 4 | E10: 5 | F10: 6 | G10: 7 | H10: 8 | I10: 9 | J10: 10 | K10: 11 | L10: 12
A11: 45961 | B11: R A Bill No 01 | C11: =Labour!C14 -> 230495000 | D11: ='Material details'!G10 -> 19375881 | E11: =C11-D11 -> 2.1111912e+08 | F11: 45870 | G11: 90.34 | H11: =AVERAGE(G11:G13) -> 90.34 | I11: =E11*0.85 -> 1.7945125e+08 | K11: 0.02 | L11: =((I11*K11*(H11-$O$11))/$O$11) -> 1209443.5 | M11: 43586 | N11: 68.52 | O11: =AVERAGE(N11:N13) -> 67.57
F12: 45901 | G12: 90.34 | M12: 43617 | N12: 67.155
F13: 45931 | G13: 90.34 | M13: 43647 | N13: 67.035
G14: =SUM(G11:G13) -> 271.02 | N14: =SUM(N11:N13) -> 202.71
C15: =SUM(C11:C14) -> 230495000 | D15: =SUM(D11:D14) -> 19375881 | E15: =SUM(E11:E14) -> 2.1111912e+08 | I15: =SUM(I11:I14) -> 1.7945125e+08 | L15: =SUM(L11:L14) -> 1209443.5

Sheet TMT
A1: STATEMENT SHOWING CALCULATION OF PRICE ESCALATION | G1: STEEL
A2: Percentage of Components as per agrement | C2: BASIC INDICES | F2: STAR RATE OF CEMENT | H2: 4700 Rs per MT | J2: STAR RATE OF STEEL | L2: 45785 Rs per MT
A3: 1 LABOUR | B3: 0.11 | C3: 1. LABOUR | E3: Agreement No
A4: 2 MATERIAL | B4: 0.76 | C4: 2. MATERIAL | E4: Name of Agency | G4: : M/s UNIVASTU INDIA LTD
A5: 3 P.O.L. | B5: 0.13 | C5: 3. P.O.L. | E5: Name of Work | G5: Construction of sub market at khedshivapur
C6: 4. CEMENT
C7: 5. STEEL | D7: =O14 -> 107.96667 | E7: Date of Receipt | G7: : 31.08.2019
A12: Period of work done considered for price Escalation | B12: R. A. Bill No. | C12: Construction of work done (B) during the period (As per column No 1 After deducting the amount of Extra items | D12: Cost of Schedule A (Cement & Steel) Material consumed for the work done during the period | E12: P = ( 3- 4 ) | F12: Month | G12: Monthly Indices for Steel | H12: Quarterly average Index Steel | I12: VL = (P x 0.85) | J12: = P (-) Cost of Schedule "A" Material used | L12: S0 (SI1-SI0) x T SI0
A13: 1 | B13: 2 | C13: 3 | D13: 4 | E13: 5 | F13: 6 | G13: 7 | H13: 8 | I13: 9 | J13: 10 | K13: 11 | L13: 12
A14: 45961 | B14: R A Bill No 01 | F14: 45870 | G14: 135.2 | H14: =AVERAGE(G14:G16) -> 135.06667 | L14: =((45700*(H14-$O$14))/$O$14)*'Material details'!D8 -> 2600901.7 | M14: 43586 | N14: 109.4 | O14: =AVERAGE(N14:N16) -> 107.96667
F15: 45901 | G15: 135.6 | M15: 43617 | N15: 108.4
F16: 45931 | G16: 134.4 | M16: 43647 | N16: 106.1
G17: =SUM(G14:G16) -> 405.2 | N17: =SUM(N14:N16) -> 323.9
L18: =SUM(L14:L17) -> 2600901.7

Sheet Cement
A1: STATEMENT SHOWING CALCULATION OF PRICE ESCALATION | G1: CEMENT
A2: Percentage of Components as per agrement | C2: BASIC INDICES | F2: STAR RATE OF CEMENT | H2: 4700 Rs per MT | J2: STAR RATE OF STEEL | L2: 45785 Rs per MT
A3: 1 LABOUR | B3: 0.11 | C3: 1. LABOUR | E3: Agreement No
A4: 2 MATERIAL | B4: 0.76 | C4: 2. MATERIAL | E4: Name of Agency | G4: : M/s UNIVASTU INDIA LTD
A5: 3 P.O.L. | B5: 0.13 | C5: 3. P.O.L. | E5: Name of Work | G5: Construction of sub market at khedshivapur
C6: 4. CEMENT | D6: =O10 -> 122.1
C7: 5. STEEL | E7: Date of Receipt | G7: : 31.08.2019
A8: Period of work done considered for price Escalation | B8: R. A. Bill No. | C8: Construction of work done (B) during the period (As per column No 1 After deducting the amount of Extra items | D8: Cost of Schedule A (Cement & Steel) Material consumed for the work done during the period | E8: P = ( 3- 4 ) | F8: Month | G8: Monthly Indices for Cement | H8: Quarterly average Index Cement | I8: VL = (P x 0.85) | J8: = P (-) Cost of Schedule "A" Material used | L8: C0 (CI1-CI0) x T CI0
A9: 1 | B9: 2 | C9: 3 | D9: 4 | E9: 5 | F9: 6 | G9: 7 | H9: 8 | I9: 9 | J9: 10 | K9: 11 | L9: 12
A10: 45961 | B10: R A Bill No 01 | F10: 45870 | G10: 130.7 | H10: =AVERAGE(G10:G12) -> 129.73333 | L10: =((5500*(H10-$O$10))/$O$10)*'Material details'!D7 -> 544955.16 | M10: 43586 | N10: 123.2 | O10: =AVERAGE(N10:N12) -> 122.1
F11: 45901 | G11: 130 | M11: 43617 | N11: 122.5
F12: 45931 | G12: 128.5 | M12: 43647 | N12: 120.6
G13: =SUM(G10:G12) -> 389.2 | L13: =SUM(L10:L12) -> 544955.16 | N13: =SUM(N10:N12) -> 366.3

Sheet Material details
A1: Agreement No
A2: Name of Agency | C2: : M/s UNIVASTU INDIA LTD
A3: Name of Work
A5: DETAILS OF MATERIAL CONSUMED IN THIS BILL
A6: Month | B6: Bill No. | C6: Material | D6: Quantity | E6: Unit | F6: Rate | G6: Amount
A7: 45961 | B7: R.A.Bill no.01 | C7: Cement | D7: =+'CEMENT-2'!G19 -> 1584.8914 | E7: M.T | F7: 4700 | G7: =D7*F7 -> 7448989.7 | H7: =290*20 -> 5800 | I7: =H7-F7 -> 1100 | J7: =D7*I7 -> 1743380.6
C8: TMT | D8: =20.12+28.29+13.85+88.92+75.56 -> 226.74 | E8: M.T | F8: 45785 | G8: =D8*F8 -> 10381291 | H8: =49000 -> 49000 | I8: =H8-F8 -> 3215 | J8: =D8*I8 -> 728969.1
C9: Structural Steel | D9: 33.6 | E9: M.T | F9: 46000 | G9: =D9*F9 -> 1545600
E10: Total R.A.Bill No.01 | G10: =SUM(G7:G9) -> 19375881
E11: Grand Total | G11: =G10 -> 19375881

Sheet CEMENT-1
A1: CEMENT CONSUMPTION STATEMENT
A2: Name of Work:- Construction of Inftrastructure Project for National Institute of Post Harvest Technology at Talegaon Dabhade Dist Pune | F2: Agreement No.:- B-1/CE/1 for 2011-2012
A3: Name of Contractor:- Prakash Constroweel Limited Nasik. Tal & Dist Nasik. | F3: Bill No.- Ist R.A.Bill
A4: Item No. | B4: Item of work in brief. | C4: Executed Quantity | D4: Therotical rate of consumption of Bitumen/Cement | E4: Unit | F4: Bitumen in M.T./ Cement in Bags | G4: Remarks.
F5: Required as per theoretical calculations.
A6: 16 | D6: 4.05 | E6: Cum | F6: =C6*D6 -> 0 | G6: M.B.No P.No
A7: 17 | D7: 3.2 | E7: Cum | F7: =C7*D7 -> 0
A8: 18 | D8: 6.8 | E8: Cum | F8: =C8*D8 -> 0
A9: 19 | D9: 6.8 | E9: Cum | F9: =C9*D9 -> 0
A10: 20 | D10: 6.8 | E10: Cum | F10: =C10*D10 -> 0
A11: 32 | D11: 1.44 | E11: Cum | F11: =C11*D11 -> 0
E12: Total | F12: =SUM(F6:F11) -> 0 | G12: =(F12*50)/1000 -> 0
G13: M.T.

Sheet Cement-Con-1
A1: CEMENT CONSUMPTION STATEMENT
A2: Sr.no. | B2: Description | C2: R.A. Bill No. 1 | D2: R.A. Bill No. 2 | E2: R.A. Bill No. 3 | F2: R.A. Bill No. 4 | G2: R.A. Bill No. 5 | H2: R.A. Bill No. 6 | I2: R.A. Bill No. 7 | J2: R.A. Bill No. 8 | K2: R.A. Bill No. 9 | L2: R.A. Bill No. 10 | M2: R.A. Bill No. 11 | N2: R.A. Bill No. 12 | O2: Total Quantity
A3: 16 | B3: P & L in situ c.c 1:3:6 | C3: 23.364 | D3: 31.8 | E3: 182.64154 | F3: 33.042 | G3: 12.3795 | J3: 2.607 | O3: =SUM(C3:N3) -> 285.83404
A4: 17 | B4: P & L in situ c.c 1:4:8 | C4: 4.46982 | E4: 12.474495 | F4: 0 | G4: 70.255073 | J4: 67.400348 | K4: 22.058257 | N4: 45.57 | O4: =SUM(C4:N4) -> 222.22799
A5: 18 | B5: P & L M-20 for Footing | C5: 46.185 | D5: 67.9605 | E5: 61.02 | F5: 56.79055 | G5: 29.221 | J5: 6.024 | O5: =SUM(C5:N5) -> 267.20105
A6: 19 | B6: P & L M-20 for Column | C6: 8.82045 | D6: 11.08485 | E6: 74.99 | F6: 85.457 | G6: 29.75 | H6: 2 | I6: 23.25645 | J6: 48.085175 | K6: 44.45 | L6: 4.7817 | M6: 22.22766 | N6: 3.91 | O6: =SUM(C6:N6) -> 358.81329
A7: 20 | B7: P & L M-20 for Beam | C7: 19.43799 | D7: 29.35536 | E7: 120.29 | F7: 48.211788 | G7: 100.31 | H7: 58.33 | I7: 2.62 | J7: 73.26 | K7: 70.94 | L7: 129.81 | N7: 30.83 | O7: =SUM(C7:N7) -> 683.39514
A8: 21 | B8: P & L M-20 for Slab | D8: 30.70304 | E8: 32.11 | F8: 43.396586 | G8: 50.09 | H8: 80.38 | I8: 133.85 | J8: 83.820025 | K8: 77.88 | L8: 130.92496 | N8: 5.2 | O8: =SUM(C8:N8) -> 668.35461
A9: 22 | B9: P & L M-20 for Lintel | E9: 4.41 | F9: 4.56 | G9: 8.37 | H9: 4.08 | I9: 15.82 | J9: 2.536985 | K9: 4.99 | L9: 12.91818 | O9: =SUM(C9:N9) -> 57.685165
A10: 23 | B10: P & L M-20 for Steps | L10: 5.985 | O10: =SUM(C10:N10) -> 5.985
A11: 24 | B11: P & L M-20 for Paradi | G11: 1.54 | L11: 8.2446 | O11: =SUM(C11:N11) -> 9.7846
A12: 25 | B12: P & L M-20 for coping | O12: =SUM(C12:N12) -> 0
A13: 26 | B13: P & L M-20 for Chajja | G13: 4.82 | I13: 2.4 | O13: =SUM(C13:N13) -> 7.22
A14: 32 | B14: BBM in CM 1:6 | C14: 13.40946 | E14: 77.75 | F14: 145.3 | G14: 39.93 | H14: 195.18 | I14: 218.8671 | J14: 175.19 | K14: 166.73 | L14: 544.47 | M14: 216.06006 | N14: 229.27 | O14: =SUM(C14:N14) -> 2022.1566
B15: BBM in CM 1:4 | H15: 24.27 | J15: 36.45 | K15: 24.3 | L15: 48.6 | O15: =SUM(C15:N15) -> 133.62
A16: 38 | B16: Plaster 20 mm | G16: 914.47 | H16: 1260.11 | I16: 1267.1565 | J16: 630.3692 | K16: 1198.14 | L16: 5818.08 | N16: 14.61 | O16: =SUM(C16:N16) -> 11102.936
A17: 36 | B17: Ceiling Plaster | F17: 176.28 | H17: 402.22 | J17: 221.3175 | K17: 386.74 | L17: 1157.92 | N17: 20.03 | O17: =SUM(C17:N17) -> 2364.5075
A18: 40 | B18: Sand Faced Plaster | J18: 1119.26 | K18: 1040.02 | L18: 1947.44 | N18: 117.95 | O18: =SUM(C18:N18) -> 4224.67
A19: 46 | B19: Vitrified Flooring Tiles | K19: 734.46 | L19: 1133.36 | M19: 1029.49 | N19: 782.03 | O19: =SUM(C19:N19) -> 3679.34
A20: 48 | B20: Vitrified Skirting | K20: 8.98 | L20: 4.34 | N20: 1.21 | O20: =SUM(C20:N20) -> 14.53
A21: 49 | B21: Ceramic flooring | M21: 218.26 | O21: =SUM(C21:N21) -> 218.26
A22: 50 | B22: Dado | M22: 726.45 | O22: =SUM(C22:N22) -> 726.45
A23: 48 | B23: Granite Skirting | M23: 47.42 | N23: 161.31 | O23: =SUM(C23:N23) -> 208.73
A24: 41 | B24: Waterproofing for W.C | M24: 223.39 | N24: 200.78 | O24: =SUM(C24:N24) -> 424.17
A25: 42 | B25: Waterproofing for terrace | M25: 15.33 | O25: =SUM(C25:N25) -> 15.33
A26: 51 | B26: Black Granite stone for treads and risers | N26: 49.32 | O26: =SUM(C26:N26) -> 49.32
A27: 52 | B27: Granite flooring for steps | O27: =SUM(C27:N27) -> 0
A28: 62 | B28: Granite for door frame | M28: 180.84 | O28: =SUM(C28:N28) -> 180.84

Sheet CEMENT-2
A1: CEMENT CONSUMPTION STATEMENT
A2: Name of Work:- Construction of sub market at Khedshivapur | F2: WO No.:- | G2: जा. क्र. प्रजा/स्थापत्य/उ. बा. खेडशीवापूर/आठ. बाजार/वर्क ऑर्डर/ २०७७/२०१९-२० दि. १९/०९/२०१९
A3: Name of Contractor:- UNIVASTU INDIA LTD | F3: Bill No.- | G3: 01
A4: Item No. | B4: Item of work in brief. | C4: Executed Quantity | D4: Therotical rate of consumption of Bitumen/Cement Bag per Unit | E4: Unit | F4: Required as per theoretical calculations. Bag | G4: Remarks.
A6: 1 | B6: M-15 Grade | C6: =135.73+71.03+136.54+189.42+1012.46+366.35 -> 1911.53 | D6: 6 | E6: Cum | F6: =C6*D6 -> 11469.18 | G6: M.B.No P.No
A7: 18 | B7: M-20 Grade | C7: =45.36+48.06+59.4+852.38 -> 1005.2 | E7: Cum | F7: =C7*D7 -> 0
A8: 19 | B8: M-20 Grade | C8: =31.73+29.78+14.7+341.77 -> 417.98 | E8: Cum | F8: =C8*D8 -> 0
A9: 20 | B9: M-20 Grade | C9: =22.02+23.37+49.68 -> 95.07 | E9: Cum | F9: =C9*D9 -> 0
B10: M-20 Grade | C10: =27.76+50.94 -> 78.7 | E10: Cum | F10: =C10*D10 -> 0
B11: M-20 Grade | C11: =39.93+100.51 -> 140.44 | E11: Cum | F11: =C11*D11 -> 0
B12: M-20 Grade | C12: =12.38+6.35 -> 18.73 | E12: Cum | F12: =C12*D12 -> 0
B13: M-20 Grade | C13: =22.03+8.07 -> 30.1 | E13: Cum | F13: =C13*D13 -> 0
B14: M-20 Grade | C14: 1.23 | E14: Cum | F14: =C14*D14 -> 0
B15: Tremix M-20 Grade | C15: =57.71+137.6 -> 195.31 | E15: Cum | F15: =C15*D15 -> 0
A16: 2 | B16: Total M-20 Garde | C16: =SUM(C7:C15) -> 1982.76 | D16: 7 | E16: Cum | F16: =C16*D16 -> 13879.32
A17: 3 | B17: Tremix M-30 Grade | C17: 343.68 | D17: 8 | E17: Cum | F17: =C17*D17 -> 2749.44
A18: 4 | B18: Cement use for other activity like plaster, flooring, eaterproofing etc. | E18: Cum | F18: 3599.8883
E19: Total In Bag | F19: =SUM(F6:F18) -> 31697.828 | G19: =(F19*50)/1000 -> 1584.8914
G20: M.T.

Sheet Indices
A1: INDICES
A2: Sr. No. | B2: Material | C2: Indices at Tender | E2: Current Indices | G2: % Above/ Below
A3: A | B3: Labour | C3: 43586 | D3: 314 | E3: 45870 | F3: 444.682 | G3: =(F3-D3)/D3*100 -> 41.618471
C4: 43617 | D4: 316 | E4: 45901 | F4: 444.682 | G4: =(F4-D4)/D4*100 -> 40.722152
C5: 43647 | D5: 319 | E5: 45931 | F5: 455.63 | G5: =(F5-D5)/D5*100 -> 42.830721
C6: Average | D6: =AVERAGE(D3:D5) -> 316.33333 | F6: =AVERAGE(F3:F5) -> 448.33133 | G6: =(F6-D6)/D6*100 -> 41.727503
A8: B | B8: Other Material | C8: 43586 | D8: 121.6 | E8: 45870 | F8: 155.2 | G8: =(F8-D8)/D8*100 -> 27.631579
C9: 43617 | D9: 121.5 | E9: 45901 | F9: 155.2 | G9: =(F9-D9)/D9*100 -> 27.736626 | I9: 181.5
C10: 43647 | D10: 121.3 | E10: 45931 | F10: 155.2 | G10: =(F10-D10)/D10*100 -> 27.947238 | I10: 179.8
C11: Average | D11: =AVERAGE(D8:D10) -> 121.46667 | F11: =AVERAGE(F8:F10) -> 155.2 | G11: =(F11-D11)/D11*100 -> 27.771679
A13: C | B13: POL | C13: 43586 | D13: 68.52 | E13: 45870 | F13: 90.34 | G13: =(F13-D13)/D13*100 -> 31.844717
C14: 43617 | D14: 67.155 | E14: 45901 | F14: 90.34 | G14: =(F14-D14)/D14*100 -> 34.524607
C15: 43647 | D15: 67.035 | E15: 45931 | F15: 90.34 | G15: =(F15-D15)/D15*100 -> 34.765421
C16: Average | D16: =AVERAGE(D13:D15) -> 67.57 | F16: =AVERAGE(F13:F15) -> 90.34 | G16: =(F16-D16)/D16*100 -> 33.698387
A18: D | B18: TMT | C18: 43586 | D18: 109.4 | E18: 45870 | F18: 135.2 | G18: =(F18-D18)/D18*100 -> 23.583181
C19: 43617 | D19: 108.4 | E19: 45901 | F19: 135.6 | G19: =(F19-D19)/D19*100 -> 25.092251
C20: 43647 | D20: 106.1 | E20: 45931 | F20: 134.4 | G20: =(F20-D20)/D20*100 -> 26.67295
C21: Average | D21: =AVERAGE(D18:D20) -> 107.96667 | F21: =AVERAGE(F18:F20) -> 135.06667 | G21: =(F21-D21)/D21*100 -> 25.10034
A23: E | B23: CEMENT | C23: 43586 | D23: 123.2 | E23: 45870 | F23: 130.7 | G23: =(F23-D23)/D23*100 -> 6.0876623
C24: 43617 | D24: 122.5 | E24: 45901 | F24: 130 | G24: =(F24-D24)/D24*100 -> 6.122449
C25: 43647 | D25: 120.6 | E25: 45931 | F25: 128.5 | G25: =(F25-D25)/D25*100 -> 6.5505804 | J25: =(F25-D25)/D25*100 -> 6.5505804
C26: Average | D26: =AVERAGE(D23:D25) -> 122.1 | F26: =AVERAGE(F23:F25) -> 129.73333 | G26: =(F26-D26)/D26*100 -> 6.2517063
G27: =(G6+G11+G16+G21+G26)/5 -> 26.909923

Sheet Corrected Index
A1: INDICES - Pune | L1: INDICES - Pune
A2: Sr. No. | B2: Month | C2: INDICES | L2: Sr. No. | M2: Month | N2: INDICES
C3: Labour | F3: POL | G3: Other Material | H3: TMT | I3: CEMENT | J3: Structural steel | N3: Labour | O3: POL | P3: Other Material | Q3: TMT | R3: CEMENT | S3: Structural steel
C4: Basic | D4: Linking Factor | E4: Final Indices
B5: 1 | C5: 2 | F5: 3 | G5: 4 | H5: 5 | I5: 6 | J5: 7 | M5: 1 | N5: 2 | O5: 3 | P5: 4 | Q5: 5 | R5: 6 | S5: 7
A6: 1 | B6: 41275 | C6: 227 | D6: 1 | E6: =C6*D6 -> 227 | F6: 53.64 | G6: 108 | H6: 100.1 | I6: 103.3 | J6: 104.9 | L6: 1 | M6: 41275 | N6: 227 | O6: 53.64 | P6: 108 | Q6: 100.1 | R6: 103.3 | S6: 104.9
A7: 2 | B7: 41306 | C7: 228 | D7: 1 | E7: =C7*D7 -> 228 | F7: 54.17 | G7: 108.4 | H7: 101.2 | I7: 104.3 | J7: 105.7 | L7: 2 | M7: 41306 | N7: 228 | O7: 54.17 | P7: 108.4 | Q7: 101.2 | R7: 104.3 | S7: 105.7
A8: 3 | B8: 41334 | C8: 227 | D8: 1 | E8: =C8*D8 -> 227 | F8: 54.77 | G8: 108.6 | H8: 99.9 | I8: 103.8 | J8: 108.2 | L8: 3 | M8: 41334 | N8: 227 | O8: 54.77 | P8: 108.6 | Q8: 99.9 | R8: 103.8 | S8: 108.2
A9: 4 | B9: 41365 | C9: 230 | D9: 1 | E9: =C9*D9 -> 230 | F9: 54.77 | G9: 108.6 | H9: 100 | I9: 102.5 | J9: 106.9 | L9: 4 | M9: 41365 | N9: 230 | O9: 54.77 | P9: 108.6 | Q9: 100 | R9: 102.5 | S9: 106.9
A10: 5 | B10: 41395 | C10: 232 | D10: 1 | E10: =C10*D10 -> 232 | F10: 55.95 | G10: 108.6 | H10: 98.9 | I10: 103.6 | J10: 105.7 | L10: 5 | M10: 41395 | N10: 232 | O10: 55.95 | P10: 108.6 | Q10: 98.9 | R10: 103.6 | S10: 105.7
A11: 6 | B11: 41426 | C11: 240 | D11: 1 | E11: =C11*D11 -> 240 | F11: 57.68 | G11: 110.1 | H11: 98.5 | I11: 106 | J11: 106.8 | L11: 6 | M11: 41426 | N11: 240 | O11: 57.68 | P11: 110.1 | Q11: 98.5 | R11: 106 | S11: 106.8
A12: 7 | B12: 41456 | C12: 239 | D12: 1 | E12: =C12*D12 -> 239 | F12: 58.28 | G12: 111.2 | H12: 97.4 | I12: 105.8 | J12: 107.3 | L12: 7 | M12: 41456 | N12: 239 | O12: 58.28 | P12: 111.2 | Q12: 97.4 | R12: 105.8 | S12: 107.3
A13: 8 | B13: 41487 | C13: 244 | D13: 1 | E13: =C13*D13 -> 244 | F13: 58.15 | G13: 112.9 | H13: 96.9 | I13: 103.4 | J13: 107.9 | L13: 8 | M13: 41487 | N13: 244 | O13: 58.15 | P13: 112.9 | Q13: 96.9 | R13: 103.4 | S13: 107.9
A14: 9 | B14: 41518 | C14: 242 | D14: 1 | E14: =C14*D14 -> 242 | F14: 58.83 | G14: 114.3 | H14: 97.7 | I14: 103.5 | J14: 110.2 | L14: 9 | M14: 41518 | N14: 242 | O14: 58.83 | P14: 114.3 | Q14: 97.7 | R14: 103.5 | S14: 110.2
A15: 10 | B15: 41548 | C15: 243 | D15: 1 | E15: =C15*D15 -> 243 | F15: 58.83 | G15: 114.6 | H15: 98.3 | I15: 104.8 | J15: 107 | L15: 10 | M15: 41548 | N15: 243 | O15: 58.83 | P15: 114.6 | Q15: 98.3 | R15: 104.8 | S15: 107
A16: 11 | B16: 41579 | C16: 246 | D16: 1 | E16: =C16*D16 -> 246 | F16: 59.98 | G16: 114.3 | H16: 98.1 | I16: 103.3 | J16: 109.1 | L16: 11 | M16: 41579 | N16: 246 | O16: 59.98 | P16: 114.3 | Q16: 98.1 | R16: 103.3 | S16: 109.1
A17: 12 | B17: 41609 | C17: 246 | D17: 1 | E17: =C17*D17 -> 246 | F17: 60.75 | G17: 113.4 | H17: 98.5 | I17: 102.4 | J17: 107.3 | L17: 12 | M17: 41609 | N17: 246 | O17: 60.75 | P17: 113.4 | Q17: 98.5 | R17: 102.4 | S17: 107.3
... A24: 19 | B24: 41821 | C24: 256 | D24: 1 | E24: =C24*D24 -> 256 | F24: 65.99 | G24: 116.7 | H24: 104.1 | I24: 114 | J24: 108.3 | L24: 19 | M24: 41821 | N24: 256 | O24: 65.99 | P24: 116.7 | Q24: 104.1 | R24: 114 | S24: 108.3
A25: 20 | B25: 41852 | C25: 260 | D25: 1 | E25: =C25*D25 -> 260 | F25: =(66.55+67.24)/2 -> 66.895 | G25: 117.2 | H25: 102.2 | I25: 112 | J25: 107.2 | L25: 20 | M25: 41852 | N25: 260 | O25: =(66.55+67.24)/2 -> 66.895 | P25: 117.2 | Q25: 102.2 | R25: 112 | S25: 107.2
A26: 21 | B26: 41883 | C26: 261 | D26: 1 | E26: =C26*D26 -> 261 | F26: 67.24 | G26: 116.4 | H26: 101.9 | I26: 109.5 | J26: 108.3 | L26: 21 | M26: 41883 | N26: 261 | O26: 67.24 | P26: 116.4 | Q26: 101.9 | R26: 109.5 | S26: 108.3
A27: 22 | B27: 41913 | C27: 259 | D27: 1 | E27: =C27*D27 -> 259 | F27: 63.52 | G27: 115.6 | H27: 102.2 | I27: 109.5 | J27: 109.3 | L27: 22 | M27: 41913 | N27: 259 | O27: 63.52 | P27: 115.6 | Q27: 102.2 | R27: 109.5 | S27: 109.3
A28: 23 | B28: 41944 | C28: 258 | D28: 1 | E28: =C28*D28 -> 258 | F28: 61.27 | G28: 114.1 | H28: 100.6 | I28: 106.7 | J28: 109 | L28: 23 | M28: 41944 | N28: 258 | O28: 61.27 | P28: 114.1 | Q28: 100.6 | R28: 106.7 | S28: 109
A29: 24 | B29: 41974 | C29: 258 | D29: 1 | E29: =C29*D29 -> 258 | F29: =(60+57.93)/2 -> 58.965 | G29: 112.1 | H29: 99 | I29: 107.9 | J29: 112.1 | L29: 24 | M29: 41974 | N29: 258 | O29: =(60+57.93)/2 -> 58.965 | P29: 112.1 | Q29: 99 | R29: 107.9 | S29: 112.1
A30: 25 | B30: 42005 | C30: 259 | D30: 1 | E30: =C30*D30 -> 259 | F30: 55.46 | G30: 110.8 | H30: 98.5 | I30: 112 | J30: 109.8 | L30: 25 | M30: 42005 | N30: 259 | O30: 55.46 | P30: 110.8 | Q30: 98.5 | R30: 112 | S30: 109.8
A31: 26 | B31: 42036 | C31: 259 | D31: 1 | E31: =C31*D31 -> 259 | F31: =(52.96+53.17)/2 -> 53.065 | G31: 109.6 | H31: 96.8 | I31: 110.2 | J31: 112.1 | L31: 26 | M31: 42036 | N31: 259 | O31: =(52.96+53.17)/2 -> 53.065 | P31: 109.6 | Q31: 96.8 | R31: 110.2 | S31: 112.1
A32: 27 | B32: 42064 | C32: 261 | D32: 1 | E32: =C32*D32 -> 261 | F32: 56.26 | G32: 109.9 | H32: 95 | I32: 110.7 | J32: 114.1 | L32: 27 | M32: 42064 | N32: 261 | O32: 56.26 | P32: 109.9 | Q32: 95 | R32: 110.7 | S32: 114.1
A33: 28 | B33: 42095 | C33: 260 | D33: 1 | E33: =C33*D33 -> 260 | F33: =(55.71+54.28)/2 -> 54.995 | G33: 110.2 | H33: 94.7 | I33: 108.3 | J33: 110.6 | L33: 28 | M33: 42095 | N33: 260 | O33: =(55.71+54.28)/2 -> 54.995 | P33: 110.2 | Q33: 94.7 | R33: 108.3 | S33: 110.6
A34: 29 | B34: 42125 | C34: 264 | D34: 1 | E34: =C34*D34 -> 264 | F34: =(56.65+59.87)/2 -> 58.26 | G34: 111.4 | H34: 92.7 | I34: 105.8 | J34: 110.6 | L34: 29 | M34: 42125 | N34: 264 | O34: =(56.65+59.87)/2 -> 58.26 | P34: 111.4 | Q34: 92.7 | R34: 105.8 | S34: 110.6
A35: 30 | B35: 42156 | C35: 266 | D35: 1 | E35: =C35*D35 -> 266 | F35: 58.52 | G35: 111.8 | H35: 91.1 | I35: 105.2 | J35: 109.9 | L35: 30 | M35: 42156 | N35: 266 | O35: 58.52 | P35: 111.8 | Q35: 91.1 | R35: 105.2 | S35: 109.9
A36: 31 | B36: 42186 | C36: 265 | D36: 1 | E36: =C36*D36 -> 265 | F36: 57.57 | G36: 111.1 | H36: 89 | I36: 106.6 | J36: 109 | L36: 31 | M36: 42186 | N36: 265 | O36: 57.57 | P36: 111.1 | Q36: 89 | R36: 106.6 | S36: 109
A37: 32 | B37: 42217 | C37: 265 | D37: 1 | E37: =C37*D37 -> 265 | F37: =(51.48+50.31)/2 -> 50.895 | G37: 110 | H37: 86.5 | I37: 107.4 | J37: 110.2 | L37: 32 | M37: 42217 | N37: 265 | O37: =(51.48+50.31)/2 -> 50.895 | P37: 110 | Q37: 86.5 | R37: 107.4 | S37: 110.2
A38: 33 | B38: 42248 | C38: 271 | D38: 1 | E38: =C38*D38 -> 271 | F38: 49.81 | G38: 109.9 | H38: 86.7 | I38: 110.3 | J38: 111.6 | L38: 33 | M38: 42248 | N38: 271 | O38: 49.81 | P38: 109.9 | Q38: 86.7 | R38: 110.3 | S38: 111.6
A39: 34 | B39: 42278 | C39: 275 | D39: 1 | E39: =C39*D39 -> 275 | F39: 49.81 | G39: 110.1 | H39: 85.3 | I39: 110.1 | J39: 109.7 | L39: 34 | M39: 42278 | N39: 275 | O39: 49.81 | P39: 110.1 | Q39: 85.3 | R39: 110.1 | S39: 109.7
A40: 35 | B40: 42309 | C40: 273 | D40: 1 | E40: =C40*D40 -> 273 | F40: 50.68 | G40: 109.9 | H40: 83.5 | I40: 109 | J40: 110.1 | L40: 35 | M40: 42309 | N40: 273 | O40: 50.68 | P40: 109.9 | Q40: 83.5 | R40: 109 | S40: 110.1
A41: 36 | B41: 42339 | C41: 272 | D41: 1 | E41: =C41*D41 -> 272 | F41: =(50.63+49.97)/2 -> 50.3 | G41: 109.4 | H41: 83.1 | I41: 107 | J41: 109.8 | L41: 36 | M41: 42339 | N41: 272 | O41: =(50.63+49.97)/2 -> 50.3 | P41: 109.4 | Q41: 83.1 | R41: 107 | S41: 109.8
A42: 37 | B42: 42370 | C42: 273 | D42: 1 | E42: =C42*D42 -> 273 | F42: 50 | G42: 108 | H42: 83.2 | I42: 104.5 | J42: 110.5 | L42: 37 | M42: 42370 | N42: 273 | O42: 50 | P42: 108 | Q42: 83.2 | R42: 104.5 | S42: 110.5
A43: 38 | B43: 42401 | C43: 269 | D43: 1 | E43: =C43*D43 -> 269 | F43: =(49.96+50.25)/2 -> 50.105 | G43: 107.1 | H43: 83 | I43: 103.6 | J43: 110.1 | L43: 38 | M43: 42401 | N43: 269 | O43: =(49.96+50.25)/2 -> 50.105 | P43: 107.1 | Q43: 83 | R43: 103.6 | S43: 110.1
A44: 39 | B44: 42430 | C44: 270 | D44: 1 | E44: =C44*D44 -> 270 | F44: =(51.76+53.71)/2 -> 52.735 | G44: 107.7 | H44: 84.9 | I44: 106 | J44: 109.9 | L44: 39 | M44: 42430 | N44: 270 | O44: =(51.76+53.71)/2 -> 52.735 | P44: 107.7 | Q44: 84.9 | R44: 106 | S44: 109.9
A45: 40 | B45: 42461 | C45: 275 | D45: 1 | E45: =C45*D45 -> 275 | F45: =(54.71+52.18)/2 -> 53.445 | G45: 109 | H45: 86 | I45: 106.3 | J45: 106.8 | L45: 40 | M45: 42461 | N45: 275 | O45: =(54.71+52.18)/2 -> 53.445 | P45: 109 | Q45: 86 | R45: 106.3 | S45: 106.8
A46: 41 | B46: 42491 | C46: 275 | D46: 1 | E46: =C46*D46 -> 275 | F46: =(55.16+55.39)/2 -> 55.275 | G46: 110.4 | H46: 86.1 | I46: 107.8 | J46: 105.6 | L46: 41 | M46: 42491 | N46: 275 | O46: =(55.16+55.39)/2 -> 55.275 | P46: 110.4 | Q46: 86.1 | R46: 107.8 | S46: 105.6
...

Sheet Corrected Index (2)
A1: INDICES - Pune | J1: INDICES - Pune
A2: Sr. No. | B2: Month | C2: INDICES | J2: Sr. No. | K2: Month | L2: INDICES
C3: Labour | D3: POL | E3: Other Material | F3: TMT | G3: CEMENT | H3: Structural steel | L3: Labour | M3: POL | N3: Other Material | O3: TMT | P3: CEMENT | Q3: Structural steel
B4: 1 | C4: 2 | D4: 3 | E4: 4 | F4: 5 | G4: 6 | H4: 7 | K4: 1 | L4: 2 | M4: 3 | N4: 4 | O4: 5 | P4: 6 | Q4: 7
A5: 1 | B5: 43586 | C5: 314 | D5: =(68.6+68.44)/2 -> 68.52 | E5: 121.6 | F5: 109.4 | G5: 123.2 | J5: 1 | K5: 43586 | L5: 314 | M5: =(68.6+68.44)/2 -> 68.52 | N5: 121.6 | O5: 109.4 | P5: 123.2
A6: =+A5+1 -> 2 | B6: 43617 | C6: 316 | D6: =(68.28+66.03)/2 -> 67.155 | E6: 121.5 | F6: 108.4 | G6: 122.5 | J6: =+J5+1 -> 2 | K6: 43617 | L6: 316 | M6: =(68.28+66.03)/2 -> 67.155 | N6: 121.5 | O6: 108.4 | P6: 122.5
A7: =+A6+1 -> 3 | B7: 43647 | C7: 319 | D7: =(66.14+67.93)/2 -> 67.035 | E7: 121.3 | F7: 106.1 | G7: 120.6 | J7: =+J6+1 -> 3 | K7: 43647 | L7: 319 | M7: =(66.14+67.93)/2 -> 67.035 | N7: 121.3 | O7: 106.1 | P7: 120.6
A8: =+A7+1 -> 4 | B8: 43678 | C8: 320 | D8: =(67.87+67.11)/2 -> 67.49 | E8: 121.5 | F8: 104.2 | G8: 118.5 | J8: =+J7+1 -> 4 | K8: 43678 | L8: 320 | M8: =(67.87+67.11)/2 -> 67.49 | N8: 121.5 | O8: 104.2 | P8: 118.5
A9: =+A8+1 -> 5 | B9: 43709 | C9: 322 | D9: =(67.08+69.29)/2 -> 68.185 | E9: 121.3 | F9: 103.4 | G9: 120.7 | J9: =+J8+1 -> 5 | K9: 43709 | L9: 322 | M9: =(67.08+69.29)/2 -> 68.185 | N9: 121.3 | O9: 103.4 | P9: 120.7
A10: =+A9+1 -> 6 | B10: 43739 | C10: 325 | D10: =(69.48+67.78)/2 -> 68.63 | E10: 122 | F10: 102.6 | G10: 118.6 | J10: =+J9+1 -> 6 | K10: 43739 | L10: 325 | M10: =(69.48+67.78)/2 -> 68.63 | N10: 122 | O10: 102.6 | P10: 118.6
A11: =+A10+1 -> 7 | B11: 43770 | C11: 328 | D11: =(67.67+67.65)/2 -> 67.66 | E11: 122.3 | F11: 101.9 | G11: 119.6 | J11: =+J10+1 -> 7 | K11: 43770 | L11: 328 | M11: =(67.67+67.65)/2 -> 67.66 | N11: 122.3 | O11: 101.9 | P11: 119.6
A12: =+A11+1 -> 8 | B12: 43800 | C12: 330 | D12: =(67.74+69.95)/2 -> 68.845 | E12: 122.8 | F12: 103.1 | G12: 119.2 | J12: =+J11+1 -> 8 | K12: 43800 | L12: 330 | M12: =(67.74+69.95)/2 -> 68.845 | N12: 122.8 | O12: 103.1 | P12: 119.2
A13: =+A12+1 -> 9 | B13: 43831 | C13: 330 | D13: =(70.11+68.23)/2 -> 69.17 | E13: 123.4 | F13: 104.9 | G13: 118 | J13: =+J12+1 -> 9 | K13: 43831 | L13: 330 | M13: =(70.11+68.23)/2 -> 69.17 | N13: 123.4 | O13: 104.9 | P13: 118
A14: =+A13+1 -> 10 | B14: 43862 | C14: 328 | D14: =(68.11+66.29)/2 -> 67.2 | E14: 122.2 | F14: 105.6 | G14: 119.8 | J14: =+J13+1 -> 10 | K14: 43862 | L14: 328 | M14: =(68.11+66.29)/2 -> 67.2 | N14: 122.2 | O14: 105.6 | P14: 119.8
A15: =+A14+1 -> 11 | B15: 43891 | C15: 326 | D15: =(66.06+63.98)/2 -> 65.02 | E15: 120.4 | F15: 106.6 | G15: 119.7 | J15: =+J14+1 -> 11 | K15: 43891 | L15: 326 | M15: =(66.06+63.98)/2 -> 65.02 | N15: 120.4 | O15: 106.6 | P15: 119.7
A16: =+A15+1 -> 12 | B16: 43922 | C16: 329 | D16: 64.98 | E16: 119.2 | F16: 106.2 | G16: 123.3 | J16: =+J15+1 -> 12 | K16: 43922 | L16: 329 | M16: 64.98 | N16: 119.2 | O16: 106.2 | P16: 123.3
A17: =+A16+1 -> 13 | B17: 43952 | C17: 330 | D17: 64.98 | E17: 117.5 | F17: 105.6 | G17: 124.6 | J17: =+J16+1 -> 13 | K17: 43952 | L17: 330 | M17: 64.98 | N17: 117.5 | O17: 105.6 | P17: 124.6
A18: =+A17+1 -> 14 | B18: 43983 | C18: 332 | D18: =(66.99+77.35)/2 -> 72.17 | E18: 119.3 | F18: 104.8 | G18: 123.2 | J18: =+J17+1 -> 14 | K18: 43983 | L18: 332 | M18: =(66.99+77.35)/2 -> 72.17 | N18: 119.3 | O18: 104.8 | P18: 123.2
A19: =+A18+1 -> 15 | B19: 44013 | C19: 336 | D19: =(77.6+78.67)/2 -> 78.135 | E19: 121 | F19: 102.8 | G19: 121.5 | J19: =+J18+1 -> 15 | K19: 44013 | L19: 336 | M19: =(77.6+78.67)/2 -> 78.135 | N19: 121 | O19: 102.8 | P19: 121.5
A20: =+A19+1 -> 16 | B20: 44044 | C20: 338 | D20: 78.67 | E20: 122 | F20: 104.5 | G20: 119.7 | J20: =+J19+1 -> 16 | K20: 44044 | L20: 338 | M20: 78.67 | N20: 122 | O20: 104.5 | P20: 119.7
A21: =+A20+1 -> 17 | B21: 44075 | C21: 369.334 | D21: =(78.51+75.67)/2 -> 77.09 | E21: 122.9 | F21: 106.3 | G21: 118.3 | J21: =+J20+1 -> 17 | K21: 44075 | L21: 369.334 | M21: =(78.51+75.67)/2 -> 77.09 | N21: 122.9 | O21: 106.3 | P21: 118.3
A22: =+A21+1 -> 18 | B22: 44105 | C22: 371.266 | D22: =(75.57+75.48)/2 -> 75.525 | E22: 123.6 | F22: 108 | G22: 117.8 | J22: =+J21+1 -> 18 | K22: 44105 | L22: 371.266 | M22: =(75.57+75.48)/2 -> 75.525 | N22: 123.6 | O22: 108 | P22: 117.8
A23: =+A22+1 -> 19 | B23: 44136 | C23: 372.876 | D23: =(75.71+77.47)/2 -> 76.59 | E23: 125.1 | F23: 112.8 | G23: 118.7 | J23: =+J22+1 -> 19 | K23: 44136 | L23: 372.876 | M23: =(75.71+77.47)/2 -> 76.59 | N23: 125.1 | O23: 112.8 | P23: 118.7
A24: =+A23+1 -> 20 | B24: 44166 | C24: 371.588 | D24: =(77.71+78.97)/2 -> 78.34 | E24: 125.4 | F24: 118.2 | G24: 118.1 | J24: =+J23+1 -> 20 | K24: 44166 | L24: 371.588 | M24: =(77.71+78.97)/2 -> 78.34 | N24: 125.4 | O24: 118.2 | P24: 118.1
A25: =+A24+1 -> 21 | B25: 44197 | C25: 371.91 | D25: =(79.25+81.72)/2 -> 80.485 | E25: 126.5 | F25: 125.6 | G25: 118.5 | J25: =+J24+1 -> 21 | K25: 44197 | L25: 371.91 | M25: =(79.25+81.72)/2 -> 80.485 | N25: 126.5 | O25: 125.6 | P25: 118.5
A26: =+A25+1 -> 22 | B26: 44228 | C26: 374.486 | D26: =(82.07+86.88)/2 -> 84.475 | E26: 128.1 | F26: 124.7 | G26: 120.6 | J26: =+J25+1 -> 22 | K26: 44228 | L26: 374.486 | M26: =(82.07+86.88)/2 -> 84.475 | N26: 128.1 | O26: 124.7 | P26: 120.6
A27: =+A26+1 -> 23 | B27: 44256 | C27: 377.062 | D27: =(86.7+86.26)/2 -> 86.48 | E27: 129.9 | F27: 124.6 | G27: 125 | J27: =+J26+1 -> 23 | K27: 44256 | L27: 377.062 | M27: =(86.7+86.26)/2 -> 86.48 | N27: 129.9 | O27: 124.6 | P27: 125
A28: =+A27+1 -> 24 | B28: 44287 | C28: 379.638 | D28: 86.11 | E28: 132 | F28: 127.6 | G28: 125.7 | J28: =+J27+1 -> 24 | K28: 44287 | L28: 379.638 | M28: 86.11 | N28: 132 | O28: 127.6 | P28: 125.7
A29: =+A28+1 -> 25 | B29: 44317 | C29: 377.062 | D29: =(86.32+90.71)/2 -> 88.515 | E29: 132.9 | F29: 130.9 | G29: 123.6 | J29: =+J28+1 -> 25 | K29: 44317 | L29: 377.062 | M29: =(86.32+90.71)/2 -> 88.515 | N29: 132.9 | O29: 130.9 | P29: 123.6
A30: =+A29+1 -> 26 | B30: 44348 | C30: 383.502 | D30: =(90.95+94.88)/2 -> 92.915 | E30: 133.7 | F30: 131.7 | G30: 123.6 | J30: =+J29+1 -> 26 | K30: 44348 | L30: 383.502 | M30: =(90.95+94.88)/2 -> 92.915 | N30: 133.7 | O30: 131.7 | P30: 123.6
A31: =+A30+1 -> 27 | B31: 44378 | C31: 388.976 | D31: =(95.07+95.6)/2 -> 95.335 | E31: 135 | F31: 131.4 | G31: 124.7 | J31: =+J30+1 -> 27 | K31: 44378 | L31: 388.976 | M31: =(95.07+95.6)/2 -> 95.335 | N31: 135 | O31: 131.4 | P31: 124.7
A32: =+A31+1 -> 28 | B32: 44409 | C32: 387.688 | D32: =(95.19+94.64)/2 -> 94.915 | E32: 136.2 | F32: 132.9 | G32: 123.3 | J32: =+J31+1 -> 28 | K32: 44409 | L32: 387.688 | M32: =(95.19+94.64)/2 -> 94.915 | N32: 136.2 | O32: 132.9 | P32: 123.3
A33: =+A32+1 -> 29 | B33: 44440 | C33: 386.078 | D33: =(94.48+95.57)/2 -> 95.025 | E33: 137.4 | F33: 133.6 | G33: 122.6 | J33: =+J32+1 -> 29 | K33: 44440 | L33: 386.078 | M33: =(94.48+95.57)/2 -> 95.025 | N33: 137.4 | O33: 133.6 | P33: 122.6
A34: =+A33+1 -> 30 | B34: 44470 | C34: 389.942 | D34: =(95.88+104.07)/2 -> 99.975 | E34: 140.7 | F34: 140.8 | G34: 125.3 | J34: =+J33+1 -> 30 | K34: 44470 | L34: 389.942 | M34: =(95.88+104.07)/2 -> 99.975 | N34: 140.7 | O34: 140.8 | P34: 125.3
A35: =+A34+1 -> 31 | B35: 44501 | C35: 391.23 | D35: =(104.46+92.3)/2 -> 98.38 | E35: 143.7 | F35: 140.4 | G35: 127.7 | J35: =+J34+1 -> 31 | K35: 44501 | L35: 391.23 | M35: =(104.46+92.3)/2 -> 98.38 | N35: 143.7 | O35: 140.4 | P35: 127.7
A36: =+A35+1 -> 32 | B36: 44531 | C36: 389.298 | D36: 92.3 | E36: 143.3 | F36: 139 | G36: 125.5 | J36: =+J35+1 -> 32 | K36: 44531 | L36: 389.298 | M36: 92.3 | N36: 143.3 | O36: 139 | P36: 125.5
A37: =+A36+1 -> 33 | B37: 44562 | C37: 388.976 | D37: 92.3 | E37: 143.8 | F37: 139.9 | G37: 124.3 | J37: =+J36+1 -> 33 | K37: 44562 | L37: 388.976 | M37: 92.3 | N37: 143.8 | O37: 139.9 | P37: 124.3
A38: =+A37+1 -> 34 | B38: 44593 | C38: 389.62 | D38: =(92.3+92.3)/2 -> 92.3 | E38: 145.3 | F38: 144.8 | G38: 127.9 | J38: =+J37+1 -> 34 | K38: 44593 | L38: 389.62 | M38: =(92.3+92.3)/2 -> 92.3 | N38: 145.3 | O38: 144.8 | P38: 127.9
A39: =+A38+1 -> 35 | B39: 44621 | C39: 391.23 | D39: =(92.3+98.93)/2 -> 95.615 | E39: 148.9 | F39: 155.9 | G39: 130.1 | J39: =+J38+1 -> 35 | K39: 44621 | L39: 391.23 | M39: =(92.3+98.93)/2 -> 95.615 | N39: 148.9 | O39: 155.9 | P39: 130.1
A40: =+A39+1 -> 36 | B40: 44652 | C40: 394.128 | D40: =(98.93+102.66)/2 -> 100.795 | E40: 152.3 | F40: 159.1 | G40: 133.5 | J40: =+J39+1 -> 36 | K40: 44652 | L40: 394.128 | M40: =(98.93+102.66)/2 -> 100.795 | N40: 152.3 | O40: 159.1 | P40: 133.5
...

Sheet Sheet2
